Workbook
Name Slicer_Dep_Name: #N/A
Name Slicer_Gender: #N/A
Name Slicer_Last_performance_rating: #N/A
Name Slicer_Left?: #N/A
Name Slicer_Title: #N/A
Name Timeline_DoJ: #N/A

Sheet Employee_Info
A1: Emp_Id | B1: DOB | C1: first_name | D1: last_name | E1: Gender | F1: DoJ | G1: no_of_projects | H1: Last_performance_rating | I1: Left? | J1: last_date | K1: Salary | L1: Dept_Id | M1: Title
A2: 10001 | B2: 9/2/1953 | C2: Georgi | D2: Facello | E2: M | F2: 6/26/1986 | G2: 9 | H2: C | I2: 1 | J2: 7/30/1994 | K2: 60117 | L2: d005 | M2: Senior Engineer
A3: 10003 | B3: 12/3/1959 | C3: Parto | D3: Bamford | E3: M | F3: 8/28/1986 | G3: 1 | H3: C | I3: 0 | K3: 40006 | L3: d004 | M3: Senior Engineer
A4: 10004 | B4: 5/1/1954 | C4: Chirstian | D4: Koblick | E4: M | F4: 12/1/1986 | G4: 5 | H4: A | I4: 0 | K4: 40054 | L4: d004 | M4: Senior Engineer
A5: 10006 | B5: 4/20/1953 | C5: Anneke | D5: Preusig | E5: F | F5: 6/2/1989 | G5: 10 | H5: B | I5: 0 | K5: 40000 | L5: d005 | M5: Senior Engineer
A6: 10002 | B6: 6/2/1964 | C6: Bezalel | D6: Simmel | E6: F | F6: 11/21/1985 | G6: 8 | H6: B | I6: 0 | K6: 65828 | L6: d007 | M6: Staff
A7: 10005 | B7: 1/21/1955 | C7: Kyoichi | D7: Maliniak | E7: M | F7: 9/12/1989 | G7: 6 | H7: A | I7: 0 | K7: 78228 | L7: d003 | M7: Staff
A8: 421786 | B8: 9/28/1957 | C8: Xiong | D8: Verhoeff | E8: M | F8: 11/26/1987 | G8: 2 | H8: C | I8: 0 | K8: 40000 | L8: d003 | M8: Staff
A9: 57444 | B9: 1/30/1958 | C9: Berry | D9: Babb | E9: F | F9: 3/21/1992 | G9: 9 | H9: A | I9: 0 | K9: 48973 | L9: d004 | M9: Engineer
A10: 10007 | B10: 5/23/1957 | C10: Tzvetan | D10: Zielinski | E10: F | F10: 2/10/1989 | G10: 6 | H10: B | I10: 1 | J10: 9/18/2002 | K10: 56724 | L10: d008 | M10: Staff
A11: 10008 | B11: 2/19/1958 | C11: Saniya | D11: Kalloufi | E11: M | F11: 9/15/1994 | G11: 9 | H11: C | I11: 0 | K11: 46671 | L11: d005 | M11: Assistant Engineer
A12: 282238 | B12: 10/28/1952 | C12: Abdelkader | D12: Baumann | E12: F | F12: 1/18/1991 | G12: 6 | H12: B | I12: 0 | K12: 40000 | L12: d006 | M12: Senior Engineer
A13: 10009 | B13: 4/19/1952 | C13: Sumant | D13: Peac | E13: F | F13: 2/18/1985 | G13: 8 | H13: B | I13: 0 | K13: 60929 | L13: d006 | M13: Senior Engineer
A14: 10010 | B14: 6/1/1963 | C14: Duangkaew | D14: Piveteau | E14: F | F14: 8/24/1989 | G14: 4 | H14: A | I14: 0 | K14: 72488 | L14: d004 | M14: Engineer
A15: 10010 | B15: 6/1/1963 | C15: Duangkaew | D15: Piveteau | E15: F | F15: 8/24/1989 | G15: 4 | H15: A | I15: 0 | K15: 72488 | L15: d006 | M15: Engineer
A16: 263976 | B16: 10/30/1959 | C16: Eran | D16: Cusworth | E16: M | F16: 11/14/1986 | G16: 8 | H16: B | I16: 1 | J16: 8/21/1993 | K16: 40000 | L16: d006 | M16: Senior Engineer
A17: 10011 | B17: 11/7/1953 | C17: Mary | D17: Sluis | E17: F | F17: 1/22/1990 | G17: 6 | H17: C | I17: 0 | K17: 42365 | L17: d009 | M17: Staff
A18: 273487 | B18: 4/14/1957 | C18: Christoph | D18: Parfitt | E18: M | F18: 6/28/1991 | G18: 10 | H18: A | I18: 0 | K18: 56087 | L18: d003 | M18: Staff
A19: 10012 | B19: 10/4/1960 | C19: Patricio | D19: Bridgland | E19: M | F19: 12/18/1992 | G19: 3 | H19: A | I19: 0 | K19: 40000 | L19: d005 | M19: Senior Engineer
A20: 10013 | B20: 6/7/1963 | C20: Eberhardt | D20: Terkki | E20: M | F20: 10/20/1985 | G20: 6 | H20: C | I20: 0 | K20: 40000 | L20: d003 | M20: Senior Staff
A21: 461591 | B21: 11/17/1964 | C21: Xudong | D21: Samarati | E21: M | F21: 11/13/1985 | G21: 2 | H21: A | I21: 1 | J21: 8/21/1994 | K21: 40000 | L21: d002 | M21: Senior Staff
A22: 10014 | B22: 2/12/1956 | C22: Berni | D22: Genin | E22: M | F22: 3/11/1987 | G22: 9 | H22: B | I22: 0 | K22: 46168 | L22: d005 | M22: Engineer
A23: 10015 | B23: 8/19/1959 | C23: Guoxiang | D23: Nooteboom | E23: M | F23: 7/2/1987 | G23: 4 | H23: B | I23: 0 | K23: 40000 | L23: d008 | M23: Senior Staff
A24: 10016 | B24: 5/2/1961 | C24: Kazuhito | D24: Cappelletti | E24: M | F24: 1/27/1995 | G24: 5 | H24: C | I24: 0 | K24: 70889 | L24: d007 | M24: Staff
A25: 10017 | B25: 7/6/1958 | C25: Cristinel | D25: Bouloucos | E25: F | F25: 8/3/1993 | G25: 10 | H25: A | I25: 0 | K25: 71380 | L25: d001 | M25: Staff
A26: 219881 | B26: 4/24/1956 | C26: Kwangyoen | D26: Speek | E26: F | F26: 2/14/1993 | G26: 6 | H26: B | I26: 0 | K26: 40000 | L26: d009 | M26: Senior Staff
A27: 10018 | B27: 6/19/1954 | C27: Kazuhide | D27: Peha | E27: F | F27: 4/3/1987 | G27: 4 | H27: B | I27: 0 | K27: 55881 | L27: d004 | M27: Senior Engineer
A28: 10018 | B28: 6/19/1954 | C28: Kazuhide | D28: Peha | E28: F | F28: 4/3/1987 | G28: 4 | H28: B | I28: 0 | K28: 55881 | L28: d005 | M28: Senior Engineer
A29: 29920 | B29: 12/31/1961 | C29: Shuichi | D29: Tyugu | E29: F | F29: 1/17/1995 | G29: 1 | H29: PIP | I29: 0 | K29: 40000 | L29: d004 | M29: Engineer
A30: 10019 | B30: 1/23/1953 | C30: Lillian | D30: Haddadi | E30: M | F30: 4/30/1999 | G30: 4 | H30: B | I30: 0 | K30: 44276 | L30: d008 | M30: Staff
A31: 10020 | B31: 12/24/1952 | C31: Mayuko | D31: Warwick | E31: M | F31: 1/26/1991 | G31: 7 | H31: B | I31: 0 | K31: 40000 | L31: d004 | M31: Engineer
A32: 208153 | B32: 10/25/1961 | C32: Abdulah | D32: Lunn | E32: M | F32: 4/8/1989 | G32: 8 | H32: C | I32: 1 | J32: 8/2/2000 | K32: 50183 | L32: d005 | M32: Senior Engineer
A33: 10021 | B33: 2/20/1960 | C33: Ramzi | D33: Erde | E33: M | F33: 2/10/1988 | G33: 1 | H33: B | I33: 0 | K33: 55025 | L33: d005 | M33: Technique Leader
A34: 10022 | B34: 7/8/1952 | C34: Shahaf | D34: Famili | E34: M | F34: 8/22/1995 | G34: 9 | H34: B | I34: 1 | J34: 11/4/2005 | K34: 40000 | L34: d005 | M34: Engineer
A35: 13616 | B35: 8/30/1961 | C35: Perry | D35: Lorho | E35: F | F35: 8/3/1991 | G35: 7 | H35: C | I35: 0 | K35: 40000 | L35: d005 | M35: Senior Engineer
A36: 13616 | B36: 8/30/1961 | C36: Perry | D36: Lorho | E36: F | F36: 8/3/1991 | G36: 7 | H36: C | I36: 0 | K36: 40000 | L36: d008 | M36: Senior Engineer
A37: 10023 | B37: 9/29/1953 | C37: Bojan | D37: Montemayor | E37: F | F37: 12/17/1989 | G37: 8 | H37: A | I37: 0 | K37: 47883 | L37: d005 | M37: Engineer
A38: 10024 | B38: 9/5/1958 | C38: Suzette | D38: Pettey | E38: F | F38: 5/19/1997 | G38: 3 | H38: A | I38: 0 | K38: 83733 | L38: d004 | M38: Assistant Engineer
A39: 246449 | B39: 3/23/1958 | C39: Subbu | D39: Bultermann | E39: F | F39: 3/25/1988 | G39: 9 | H39: C | I39: 0 | K39: 87084 | L39: d007 | M39: Staff
A40: 10025 | B40: 10/31/1958 | C40: Prasadram | D40: Heyers | E40: M | F40: 8/17/1987 | G40: 6 | H40: C | I40: 0 | K40: 40000 | L40: d005 | M40: Technique Leader
...

Sheet New_employee(Cleaned)
A1: Emp_Id | B1: DOB | C1: first_name | D1: last_name | E1: Gender | F1: DoJ | G1: no_of_projects | H1: Last_performance_rating | I1: Left? | J1: last_date | K1: Salary | L1: Dept_Id | M1: Title | N1: Performance issues?
A2: 10001 | B2: 19604 | C2: Georgi | D2: Facello | E2: M | F2: 31589 | G2: 9 | H2: C | I2: 1 | J2: 34545 | K2: 60117 | L2: d005 | M2: Senior Engineer | N2: =IF(AND( Table15[[#This Row],[Salary]] >= 80000, OR(Table15[[#This Row],[Last_performance_rating]] = "C", Table15[[#This Row],[Last_performance_rating]] = "PIP")) = TRUE, 1, 0) -> 0
A3: 10003 | B3: 21887 | C3: Parto | D3: Bamford | E3: M | F3: 31652 | G3: 1 | H3: C | I3: 0 | K3: 40006 | L3: d004 | M3: Senior Engineer | N3: =IF(AND( Table15[[#This Row],[Salary]] >= 80000, OR(Table15[[#This Row],[Last_performance_rating]] = "C", Table15[[#This Row],[Last_performance_rating]] = "PIP")) = TRUE, 1, 0) -> 0
A4: 10004 | B4: 19845 | C4: Chirstian | D4: Koblick | E4: M | F4: 31747 | G4: 5 | H4: A | I4: 0 | K4: 40054 | L4: d004 | M4: Senior Engineer | N4: =IF(AND( Table15[[#This Row],[Salary]] >= 80000, OR(Table15[[#This Row],[Last_performance_rating]] = "C", Table15[[#This Row],[Last_performance_rating]] = "PIP")) = TRUE, 1, 0) -> 0
A5: 10006 | B5: 19469 | C5: Anneke | D5: Preusig | E5: F | F5: 32661 | G5: 10 | H5: B | I5: 0 | K5: 40000 | L5: d005 | M5: Senior Engineer | N5: =IF(AND( Table15[[#This Row],[Salary]] >= 80000, OR(Table15[[#This Row],[Last_performance_rating]] = "C", Table15[[#This Row],[Last_performance_rating]] = "PIP")) = TRUE, 1, 0) -> 0
A6: 10002 | B6: 23530 | C6: Bezalel | D6: Simmel | E6: F | F6: 31372 | G6: 8 | H6: B | I6: 0 | K6: 65828 | L6: d007 | M6: Staff | N6: =IF(AND( Table15[[#This Row],[Salary]] >= 80000, OR(Table15[[#This Row],[Last_performance_rating]] = "C", Table15[[#This Row],[Last_performance_rating]] = "PIP")) = TRUE, 1, 0) -> 0
A7: 10005 | B7: 20110 | C7: Kyoichi | D7: Maliniak | E7: M | F7: 32763 | G7: 6 | H7: A | I7: 0 | K7: 78228 | L7: d003 | M7: Staff | N7: =IF(AND( Table15[[#This Row],[Salary]] >= 80000, OR(Table15[[#This Row],[Last_performance_rating]] = "C", Table15[[#This Row],[Last_performance_rating]] = "PIP")) = TRUE, 1, 0) -> 0
A8: 421786 | B8: 21091 | C8: Xiong | D8: Verhoeff | E8: M | F8: 32107 | G8: 2 | H8: C | I8: 0 | K8: 40000 | L8: d003 | M8: Staff | N8: =IF(AND( Table15[[#This Row],[Salary]] >= 80000, OR(Table15[[#This Row],[Last_performance_rating]] = "C", Table15[[#This Row],[Last_performance_rating]] = "PIP")) = TRUE, 1, 0) -> 0
A9: 57444 | B9: 21215 | C9: Berry | D9: Babb | E9: F | F9: 33684 | G9: 9 | H9: A | I9: 0 | K9: 48973 | L9: d004 | M9: Engineer | N9: =IF(AND( Table15[[#This Row],[Salary]] >= 80000, OR(Table15[[#This Row],[Last_performance_rating]] = "C", Table15[[#This Row],[Last_performance_rating]] = "PIP")) = TRUE, 1, 0) -> 0
A10: 10007 | B10: 20963 | C10: Tzvetan | D10: Zielinski | E10: F | F10: 32549 | G10: 6 | H10: B | I10: 1 | J10: 37517 | K10: 56724 | L10: d008 | M10: Staff | N10: =IF(AND( Table15[[#This Row],[Salary]] >= 80000, OR(Table15[[#This Row],[Last_performance_rating]] = "C", Table15[[#This Row],[Last_performance_rating]] = "PIP")) = TRUE, 1, 0) -> 0
A11: 10008 | B11: 21235 | C11: Saniya | D11: Kalloufi | E11: M | F11: 34592 | G11: 9 | H11: C | I11: 0 | K11: 46671 | L11: d005 | M11: Assistant Engineer | N11: =IF(AND( Table15[[#This Row],[Salary]] >= 80000, OR(Table15[[#This Row],[Last_performance_rating]] = "C", Table15[[#This Row],[Last_performance_rating]] = "PIP")) = TRUE, 1, 0) -> 0
A12: 282238 | B12: 19295 | C12: Abdelkader | D12: Baumann | E12: F | F12: 33256 | G12: 6 | H12: B | I12: 0 | K12: 40000 | L12: d006 | M12: Senior Engineer | N12: =IF(AND( Table15[[#This Row],[Salary]] >= 80000, OR(Table15[[#This Row],[Last_performance_rating]] = "C", Table15[[#This Row],[Last_performance_rating]] = "PIP")) = TRUE, 1, 0) -> 0
A13: 10009 | B13: 19103 | C13: Sumant | D13: Peac | E13: F | F13: 31096 | G13: 8 | H13: B | I13: 0 | K13: 60929 | L13: d006 | M13: Senior Engineer | N13: =IF(AND( Table15[[#This Row],[Salary]] >= 80000, OR(Table15[[#This Row],[Last_performance_rating]] = "C", Table15[[#This Row],[Last_performance_rating]] = "PIP")) = TRUE, 1, 0) -> 0
A14: 10010 | B14: 23163 | C14: Duangkaew | D14: Piveteau | E14: F | F14: 32744 | G14: 4 | H14: A | I14: 0 | K14: 72488 | L14: d004 | M14: Engineer | N14: =IF(AND( Table15[[#This Row],[Salary]] >= 80000, OR(Table15[[#This Row],[Last_performance_rating]] = "C", Table15[[#This Row],[Last_performance_rating]] = "PIP")) = TRUE, 1, 0) -> 0
A15: 10010 | B15: 23163 | C15: Duangkaew | D15: Piveteau | E15: F | F15: 32744 | G15: 4 | H15: A | I15: 0 | K15: 72488 | L15: d006 | M15: Engineer | N15: =IF(AND( Table15[[#This Row],[Salary]] >= 80000, OR(Table15[[#This Row],[Last_performance_rating]] = "C", Table15[[#This Row],[Last_performance_rating]] = "PIP")) = TRUE, 1, 0) -> 0
A16: 263976 | B16: 21853 | C16: Eran | D16: Cusworth | E16: M | F16: 31730 | G16: 8 | H16: B | I16: 1 | J16: 34202 | K16: 40000 | L16: d006 | M16: Senior Engineer | N16: =IF(AND( Table15[[#This Row],[Salary]] >= 80000, OR(Table15[[#This Row],[Last_performance_rating]] = "C", Table15[[#This Row],[Last_performance_rating]] = "PIP")) = TRUE, 1, 0) -> 0
A17: 10011 | B17: 19670 | C17: Mary | D17: Sluis | E17: F | F17: 32895 | G17: 6 | H17: C | I17: 0 | K17: 42365 | L17: d009 | M17: Staff | N17: =IF(AND( Table15[[#This Row],[Salary]] >= 80000, OR(Table15[[#This Row],[Last_performance_rating]] = "C", Table15[[#This Row],[Last_performance_rating]] = "PIP")) = TRUE, 1, 0) -> 0
A18: 273487 | B18: 20924 | C18: Christoph | D18: Parfitt | E18: M | F18: 33417 | G18: 10 | H18: A | I18: 0 | K18: 56087 | L18: d003 | M18: Staff | N18: =IF(AND( Table15[[#This Row],[Salary]] >= 80000, OR(Table15[[#This Row],[Last_performance_rating]] = "C", Table15[[#This Row],[Last_performance_rating]] = "PIP")) = TRUE, 1, 0) -> 0
A19: 10012 | B19: 22193 | C19: Patricio | D19: Bridgland | E19: M | F19: 33956 | G19: 3 | H19: A | I19: 0 | K19: 40000 | L19: d005 | M19: Senior Engineer | N19: =IF(AND( Table15[[#This Row],[Salary]] >= 80000, OR(Table15[[#This Row],[Last_performance_rating]] = "C", Table15[[#This Row],[Last_performance_rating]] = "PIP")) = TRUE, 1, 0) -> 0
A20: 10013 | B20: 23169 | C20: Eberhardt | D20: Terkki | E20: M | F20: 31340 | G20: 6 | H20: C | I20: 0 | K20: 40000 | L20: d003 | M20: Senior Staff | N20: =IF(AND( Table15[[#This Row],[Salary]] >= 80000, OR(Table15[[#This Row],[Last_performance_rating]] = "C", Table15[[#This Row],[Last_performance_rating]] = "PIP")) = TRUE, 1, 0) -> 0
A21: 461591 | B21: 23698 | C21: Xudong | D21: Samarati | E21: M | F21: 31364 | G21: 2 | H21: A | I21: 1 | J21: 34567 | K21: 40000 | L21: d002 | M21: Senior Staff | N21: =IF(AND( Table15[[#This Row],[Salary]] >= 80000, OR(Table15[[#This Row],[Last_performance_rating]] = "C", Table15[[#This Row],[Last_performance_rating]] = "PIP")) = TRUE, 1, 0) -> 0
A22: 10014 | B22: 20497 | C22: Berni | D22: Genin | E22: M | F22: 31847 | G22: 9 | H22: B | I22: 0 | K22: 46168 | L22: d005 | M22: Engineer | N22: =IF(AND( Table15[[#This Row],[Salary]] >= 80000, OR(Table15[[#This Row],[Last_performance_rating]] = "C", Table15[[#This Row],[Last_performance_rating]] = "PIP")) = TRUE, 1, 0) -> 0
A23: 10015 | B23: 21781 | C23: Guoxiang | D23: Nooteboom | E23: M | F23: 31960 | G23: 4 | H23: B | I23: 0 | K23: 40000 | L23: d008 | M23: Senior Staff | N23: =IF(AND( Table15[[#This Row],[Salary]] >= 80000, OR(Table15[[#This Row],[Last_performance_rating]] = "C", Table15[[#This Row],[Last_performance_rating]] = "PIP")) = TRUE, 1, 0) -> 0
A24: 10016 | B24: 22403 | C24: Kazuhito | D24: Cappelletti | E24: M | F24: 34726 | G24: 5 | H24: C | I24: 0 | K24: 70889 | L24: d007 | M24: Staff | N24: =IF(AND( Table15[[#This Row],[Salary]] >= 80000, OR(Table15[[#This Row],[Last_performance_rating]] = "C", Table15[[#This Row],[Last_performance_rating]] = "PIP")) = TRUE, 1, 0) -> 0
A25: 10017 | B25: 21372 | C25: Cristinel | D25: Bouloucos | E25: F | F25: 34184 | G25: 10 | H25: A | I25: 0 | K25: 71380 | L25: d001 | M25: Staff | N25: =IF(AND( Table15[[#This Row],[Salary]] >= 80000, OR(Table15[[#This Row],[Last_performance_rating]] = "C", Table15[[#This Row],[Last_performance_rating]] = "PIP")) = TRUE, 1, 0) -> 0
A26: 219881 | B26: 20569 | C26: Kwangyoen | D26: Speek | E26: F | F26: 34014 | G26: 6 | H26: B | I26: 0 | K26: 40000 | L26: d009 | M26: Senior Staff | N26: =IF(AND( Table15[[#This Row],[Salary]] >= 80000, OR(Table15[[#This Row],[Last_performance_rating]] = "C", Table15[[#This Row],[Last_performance_rating]] = "PIP")) = TRUE, 1, 0) -> 0
A27: 10018 | B27: 19894 | C27: Kazuhide | D27: Peha | E27: F | F27: 31870 | G27: 4 | H27: B | I27: 0 | K27: 55881 | L27: d004 | M27: Senior Engineer | N27: =IF(AND( Table15[[#This Row],[Salary]] >= 80000, OR(Table15[[#This Row],[Last_performance_rating]] = "C", Table15[[#This Row],[Last_performance_rating]] = "PIP")) = TRUE, 1, 0) -> 0
A28: 10018 | B28: 19894 | C28: Kazuhide | D28: Peha | E28: F | F28: 31870 | G28: 4 | H28: B | I28: 0 | K28: 55881 | L28: d005 | M28: Senior Engineer | N28: =IF(AND( Table15[[#This Row],[Salary]] >= 80000, OR(Table15[[#This Row],[Last_performance_rating]] = "C", Table15[[#This Row],[Last_performance_rating]] = "PIP")) = TRUE, 1, 0) -> 0
A29: 29920 | B29: 22646 | C29: Shuichi | D29: Tyugu | E29: F | F29: 34716 | G29: 1 | H29: PIP | I29: 0 | K29: 40000 | L29: d004 | M29: Engineer | N29: =IF(AND( Table15[[#This Row],[Salary]] >= 80000, OR(Table15[[#This Row],[Last_performance_rating]] = "C", Table15[[#This Row],[Last_performance_rating]] = "PIP")) = TRUE, 1, 0) -> 0
A30: 10019 | B30: 19382 | C30: Lillian | D30: Haddadi | E30: M | F30: 36280 | G30: 4 | H30: B | I30: 0 | K30: 44276 | L30: d008 | M30: Staff | N30: =IF(AND( Table15[[#This Row],[Salary]] >= 80000, OR(Table15[[#This Row],[Last_performance_rating]] = "C", Table15[[#This Row],[Last_performance_rating]] = "PIP")) = TRUE, 1, 0) -> 0
A31: 10020 | B31: 19352 | C31: Mayuko | D31: Warwick | E31: M | F31: 33264 | G31: 7 | H31: B | I31: 0 | K31: 40000 | L31: d004 | M31: Engineer | N31: =IF(AND( Table15[[#This Row],[Salary]] >= 80000, OR(Table15[[#This Row],[Last_performance_rating]] = "C", Table15[[#This Row],[Last_performance_rating]] = "PIP")) = TRUE, 1, 0) -> 0
A32: 208153 | B32: 22579 | C32: Abdulah | D32: Lunn | E32: M | F32: 32606 | G32: 8 | H32: C | I32: 1 | J32: 36740 | K32: 50183 | L32: d005 | M32: Senior Engineer | N32: =IF(AND( Table15[[#This Row],[Salary]] >= 80000, OR(Table15[[#This Row],[Last_performance_rating]] = "C", Table15[[#This Row],[Last_performance_rating]] = "PIP")) = TRUE, 1, 0) -> 0
A33: 10021 | B33: 21966 | C33: Ramzi | D33: Erde | E33: M | F33: 32183 | G33: 1 | H33: B | I33: 0 | K33: 55025 | L33: d005 | M33: Technique Leader | N33: =IF(AND( Table15[[#This Row],[Salary]] >= 80000, OR(Table15[[#This Row],[Last_performance_rating]] = "C", Table15[[#This Row],[Last_performance_rating]] = "PIP")) = TRUE, 1, 0) -> 0
A34: 10022 | B34: 19183 | C34: Shahaf | D34: Famili | E34: M | F34: 34933 | G34: 9 | H34: B | I34: 1 | J34: 38660 | K34: 40000 | L34: d005 | M34: Engineer | N34: =IF(AND( Table15[[#This Row],[Salary]] >= 80000, OR(Table15[[#This Row],[Last_performance_rating]] = "C", Table15[[#This Row],[Last_performance_rating]] = "PIP")) = TRUE, 1, 0) -> 0
A35: 13616 | B35: 22523 | C35: Perry | D35: Lorho | E35: F | F35: 33453 | G35: 7 | H35: C | I35: 0 | K35: 40000 | L35: d005 | M35: Senior Engineer | N35: =IF(AND( Table15[[#This Row],[Salary]] >= 80000, OR(Table15[[#This Row],[Last_performance_rating]] = "C", Table15[[#This Row],[Last_performance_rating]] = "PIP")) = TRUE, 1, 0) -> 0
A36: 13616 | B36: 22523 | C36: Perry | D36: Lorho | E36: F | F36: 33453 | G36: 7 | H36: C | I36: 0 | K36: 40000 | L36: d008 | M36: Senior Engineer | N36: =IF(AND( Table15[[#This Row],[Salary]] >= 80000, OR(Table15[[#This Row],[Last_performance_rating]] = "C", Table15[[#This Row],[Last_performance_rating]] = "PIP")) = TRUE, 1, 0) -> 0
A37: 10023 | B37: 19631 | C37: Bojan | D37: Montemayor | E37: F | F37: 32859 | G37: 8 | H37: A | I37: 0 | K37: 47883 | L37: d005 | M37: Engineer | N37: =IF(AND( Table15[[#This Row],[Salary]] >= 80000, OR(Table15[[#This Row],[Last_performance_rating]] = "C", Table15[[#This Row],[Last_performance_rating]] = "PIP")) = TRUE, 1, 0) -> 0
A38: 10024 | B38: 21433 | C38: Suzette | D38: Pettey | E38: F | F38: 35569 | G38: 3 | H38: A | I38: 0 | K38: 83733 | L38: d004 | M38: Assistant Engineer | N38: =IF(AND( Table15[[#This Row],[Salary]] >= 80000, OR(Table15[[#This Row],[Last_performance_rating]] = "C", Table15[[#This Row],[Last_performance_rating]] = "PIP")) = TRUE, 1, 0) -> 0
A39: 246449 | B39: 21267 | C39: Subbu | D39: Bultermann | E39: F | F39: 32227 | G39: 9 | H39: C | I39: 0 | K39: 87084 | L39: d007 | M39: Staff | N39: =IF(AND( Table15[[#This Row],[Salary]] >= 80000, OR(Table15[[#This Row],[Last_performance_rating]] = "C", Table15[[#This Row],[Last_performance_rating]] = "PIP")) = TRUE, 1, 0) -> 1
A40: 10025 | B40: 21489 | C40: Prasadram | D40: Heyers | E40: M | F40: 32006 | G40: 6 | H40: C | I40: 0 | K40: 40000 | L40: d005 | M40: Technique Leader | N40: =IF(AND( Table15[[#This Row],[Salary]] >= 80000, OR(Table15[[#This Row],[Last_performance_rating]] = "C", Table15[[#This Row],[Last_performance_rating]] = "PIP")) = TRUE, 1, 0) -> 0
...

Sheet Emp
A1: Emp_Id | B1: DOB | C1: first_name | D1: last_name | E1: Gender | F1: DoJ | G1: no_of_projects | H1: Last_performance_rating | I1: Left? | J1: last_date | K1: Salary | L1: Dept_Id | M1: Title | N1: DepName
A2: 10001 | B2: 9/2/1953 | C2: Georgi | D2: Facello | E2: M | F2: 6/26/1986 | G2: 9 | H2: C | I2: 1 | J2: 7/30/1994 | K2: 60117 | L2: d005 | M2: Senior Engineer | N2: =INDEX(Table3[#All], MATCH(Table13[[#This Row],[Dept_Id]], Table3[[#All],[Dept_Id]], 0), 1) -> Development
A3: 10003 | B3: 12/3/1959 | C3: Parto | D3: Bamford | E3: M | F3: 8/28/1986 | G3: 1 | H3: C | I3: 0 | K3: 40006 | L3: d004 | M3: Senior Engineer | N3: =INDEX(Table3[#All], MATCH(Table13[[#This Row],[Dept_Id]], Table3[[#All],[Dept_Id]], 0), 1) -> Production
A4: 10004 | B4: 5/1/1954 | C4: Chirstian | D4: Koblick | E4: M | F4: 12/1/1986 | G4: 5 | H4: A | I4: 0 | K4: 40054 | L4: d004 | M4: Senior Engineer | N4: =INDEX(Table3[#All], MATCH(Table13[[#This Row],[Dept_Id]], Table3[[#All],[Dept_Id]], 0), 1) -> Production
A5: 10006 | B5: 4/20/1953 | C5: Anneke | D5: Preusig | E5: F | F5: 6/2/1989 | G5: 10 | H5: B | I5: 0 | K5: 40000 | L5: d005 | M5: Senior Engineer | N5: =INDEX(Table3[#All], MATCH(Table13[[#This Row],[Dept_Id]], Table3[[#All],[Dept_Id]], 0), 1) -> Development
A6: 10002 | B6: 6/2/1964 | C6: Bezalel | D6: Simmel | E6: F | F6: 11/21/1985 | G6: 8 | H6: B | I6: 0 | K6: 65828 | L6: d007 | M6: Staff | N6: =INDEX(Table3[#All], MATCH(Table13[[#This Row],[Dept_Id]], Table3[[#All],[Dept_Id]], 0), 1) -> Sales
A7: 10005 | B7: 1/21/1955 | C7: Kyoichi | D7: Maliniak | E7: M | F7: 9/12/1989 | G7: 6 | H7: A | I7: 0 | K7: 78228 | L7: d003 | M7: Staff | N7: =INDEX(Table3[#All], MATCH(Table13[[#This Row],[Dept_Id]], Table3[[#All],[Dept_Id]], 0), 1) -> Human Resources
A8: 421786 | B8: 9/28/1957 | C8: Xiong | D8: Verhoeff | E8: M | F8: 11/26/1987 | G8: 2 | H8: C | I8: 0 | K8: 40000 | L8: d003 | M8: Staff | N8: =INDEX(Table3[#All], MATCH(Table13[[#This Row],[Dept_Id]], Table3[[#All],[Dept_Id]], 0), 1) -> Human Resources
A9: 57444 | B9: 1/30/1958 | C9: Berry | D9: Babb | E9: F | F9: 3/21/1992 | G9: 9 | H9: A | I9: 0 | K9: 48973 | L9: d004 | M9: Engineer | N9: =INDEX(Table3[#All], MATCH(Table13[[#This Row],[Dept_Id]], Table3[[#All],[Dept_Id]], 0), 1) -> Production
A10: 10007 | B10: 5/23/1957 | C10: Tzvetan | D10: Zielinski | E10: F | F10: 2/10/1989 | G10: 6 | H10: B | I10: 1 | J10: 9/18/2002 | K10: 56724 | L10: d008 | M10: Staff | N10: =INDEX(Table3[#All], MATCH(Table13[[#This Row],[Dept_Id]], Table3[[#All],[Dept_Id]], 0), 1) -> Research
A11: 10008 | B11: 2/19/1958 | C11: Saniya | D11: Kalloufi | E11: M | F11: 9/15/1994 | G11: 9 | H11: C | I11: 0 | K11: 46671 | L11: d005 | M11: Assistant Engineer | N11: =INDEX(Table3[#All], MATCH(Table13[[#This Row],[Dept_Id]], Table3[[#All],[Dept_Id]], 0), 1) -> Development
A12: 282238 | B12: 10/28/1952 | C12: Abdelkader | D12: Baumann | E12: F | F12: 1/18/1991 | G12: 6 | H12: B | I12: 0 | K12: 40000 | L12: d006 | M12: Senior Engineer | N12: =INDEX(Table3[#All], MATCH(Table13[[#This Row],[Dept_Id]], Table3[[#All],[Dept_Id]], 0), 1) -> Quality Management
A13: 10009 | B13: 4/19/1952 | C13: Sumant | D13: Peac | E13: F | F13: 2/18/1985 | G13: 8 | H13: B | I13: 0 | K13: 60929 | L13: d006 | M13: Senior Engineer | N13: =INDEX(Table3[#All], MATCH(Table13[[#This Row],[Dept_Id]], Table3[[#All],[Dept_Id]], 0), 1) -> Quality Management
A14: 10010 | B14: 6/1/1963 | C14: Duangkaew | D14: Piveteau | E14: F | F14: 8/24/1989 | G14: 4 | H14: A | I14: 0 | K14: 72488 | L14: d004 | M14: Engineer | N14: =INDEX(Table3[#All], MATCH(Table13[[#This Row],[Dept_Id]], Table3[[#All],[Dept_Id]], 0), 1) -> Production
A15: 10010 | B15: 6/1/1963 | C15: Duangkaew | D15: Piveteau | E15: F | F15: 8/24/1989 | G15: 4 | H15: A | I15: 0 | K15: 72488 | L15: d006 | M15: Engineer | N15: =INDEX(Table3[#All], MATCH(Table13[[#This Row],[Dept_Id]], Table3[[#All],[Dept_Id]], 0), 1) -> Quality Management
A16: 263976 | B16: 10/30/1959 | C16: Eran | D16: Cusworth | E16: M | F16: 11/14/1986 | G16: 8 | H16: B | I16: 1 | J16: 8/21/1993 | K16: 40000 | L16: d006 | M16: Senior Engineer | N16: =INDEX(Table3[#All], MATCH(Table13[[#This Row],[Dept_Id]], Table3[[#All],[Dept_Id]], 0), 1) -> Quality Management
A17: 10011 | B17: 11/7/1953 | C17: Mary | D17: Sluis | E17: F | F17: 1/22/1990 | G17: 6 | H17: C | I17: 0 | K17: 42365 | L17: d009 | M17: Staff | N17: =INDEX(Table3[#All], MATCH(Table13[[#This Row],[Dept_Id]], Table3[[#All],[Dept_Id]], 0), 1) -> Customer Service
A18: 273487 | B18: 4/14/1957 | C18: Christoph | D18: Parfitt | E18: M | F18: 6/28/1991 | G18: 10 | H18: A | I18: 0 | K18: 56087 | L18: d003 | M18: Staff | N18: =INDEX(Table3[#All], MATCH(Table13[[#This Row],[Dept_Id]], Table3[[#All],[Dept_Id]], 0), 1) -> Human Resources
A19: 10012 | B19: 10/4/1960 | C19: Patricio | D19: Bridgland | E19: M | F19: 12/18/1992 | G19: 3 | H19: A | I19: 0 | K19: 40000 | L19: d005 | M19: Senior Engineer | N19: =INDEX(Table3[#All], MATCH(Table13[[#This Row],[Dept_Id]], Table3[[#All],[Dept_Id]], 0), 1) -> Development
A20: 10013 | B20: 6/7/1963 | C20: Eberhardt | D20: Terkki | E20: M | F20: 10/20/1985 | G20: 6 | H20: C | I20: 0 | K20: 40000 | L20: d003 | M20: Senior Staff | N20: =INDEX(Table3[#All], MATCH(Table13[[#This Row],[Dept_Id]], Table3[[#All],[Dept_Id]], 0), 1) -> Human Resources
A21: 461591 | B21: 11/17/1964 | C21: Xudong | D21: Samarati | E21: M | F21: 11/13/1985 | G21: 2 | H21: A | I21: 1 | J21: 8/21/1994 | K21: 40000 | L21: d002 | M21: Senior Staff | N21: =INDEX(Table3[#All], MATCH(Table13[[#This Row],[Dept_Id]], Table3[[#All],[Dept_Id]], 0), 1) -> Finance
A22: 10014 | B22: 2/12/1956 | C22: Berni | D22: Genin | E22: M | F22: 3/11/1987 | G22: 9 | H22: B | I22: 0 | K22: 46168 | L22: d005 | M22: Engineer | N22: =INDEX(Table3[#All], MATCH(Table13[[#This Row],[Dept_Id]], Table3[[#All],[Dept_Id]], 0), 1) -> Development
A23: 10015 | B23: 8/19/1959 | C23: Guoxiang | D23: Nooteboom | E23: M | F23: 7/2/1987 | G23: 4 | H23: B | I23: 0 | K23: 40000 | L23: d008 | M23: Senior Staff | N23: =INDEX(Table3[#All], MATCH(Table13[[#This Row],[Dept_Id]], Table3[[#All],[Dept_Id]], 0), 1) -> Research
A24: 10016 | B24: 5/2/1961 | C24: Kazuhito | D24: Cappelletti | E24: M | F24: 1/27/1995 | G24: 5 | H24: C | I24: 0 | K24: 70889 | L24: d007 | M24: Staff | N24: =INDEX(Table3[#All], MATCH(Table13[[#This Row],[Dept_Id]], Table3[[#All],[Dept_Id]], 0), 1) -> Sales
A25: 10017 | B25: 7/6/1958 | C25: Cristinel | D25: Bouloucos | E25: F | F25: 8/3/1993 | G25: 10 | H25: A | I25: 0 | K25: 71380 | L25: d001 | M25: Staff | N25: =INDEX(Table3[#All], MATCH(Table13[[#This Row],[Dept_Id]], Table3[[#All],[Dept_Id]], 0), 1) -> Marketing
A26: 219881 | B26: 4/24/1956 | C26: Kwangyoen | D26: Speek | E26: F | F26: 2/14/1993 | G26: 6 | H26: B | I26: 0 | K26: 40000 | L26: d009 | M26: Senior Staff | N26: =INDEX(Table3[#All], MATCH(Table13[[#This Row],[Dept_Id]], Table3[[#All],[Dept_Id]], 0), 1) -> Customer Service
A27: 10018 | B27: 6/19/1954 | C27: Kazuhide | D27: Peha | E27: F | F27: 4/3/1987 | G27: 4 | H27: B | I27: 0 | K27: 55881 | L27: d004 | M27: Senior Engineer | N27: =INDEX(Table3[#All], MATCH(Table13[[#This Row],[Dept_Id]], Table3[[#All],[Dept_Id]], 0), 1) -> Production
A28: 10018 | B28: 6/19/1954 | C28: Kazuhide | D28: Peha | E28: F | F28: 4/3/1987 | G28: 4 | H28: B | I28: 0 | K28: 55881 | L28: d005 | M28: Senior Engineer | N28: =INDEX(Table3[#All], MATCH(Table13[[#This Row],[Dept_Id]], Table3[[#All],[Dept_Id]], 0), 1) -> Development
A29: 29920 | B29: 12/31/1961 | C29: Shuichi | D29: Tyugu | E29: F | F29: 1/17/1995 | G29: 1 | H29: PIP | I29: 0 | K29: 40000 | L29: d004 | M29: Engineer | N29: =INDEX(Table3[#All], MATCH(Table13[[#This Row],[Dept_Id]], Table3[[#All],[Dept_Id]], 0), 1) -> Production
A30: 10019 | B30: 1/23/1953 | C30: Lillian | D30: Haddadi | E30: M | F30: 4/30/1999 | G30: 4 | H30: B | I30: 0 | K30: 44276 | L30: d008 | M30: Staff | N30: =INDEX(Table3[#All], MATCH(Table13[[#This Row],[Dept_Id]], Table3[[#All],[Dept_Id]], 0), 1) -> Research
A31: 10020 | B31: 12/24/1952 | C31: Mayuko | D31: Warwick | E31: M | F31: 1/26/1991 | G31: 7 | H31: B | I31: 0 | K31: 40000 | L31: d004 | M31: Engineer | N31: =INDEX(Table3[#All], MATCH(Table13[[#This Row],[Dept_Id]], Table3[[#All],[Dept_Id]], 0), 1) -> Production
A32: 208153 | B32: 10/25/1961 | C32: Abdulah | D32: Lunn | E32: M | F32: 4/8/1989 | G32: 8 | H32: C | I32: 1 | J32: 8/2/2000 | K32: 50183 | L32: d005 | M32: Senior Engineer | N32: =INDEX(Table3[#All], MATCH(Table13[[#This Row],[Dept_Id]], Table3[[#All],[Dept_Id]], 0), 1) -> Development
A33: 10021 | B33: 2/20/1960 | C33: Ramzi | D33: Erde | E33: M | F33: 2/10/1988 | G33: 1 | H33: B | I33: 0 | K33: 55025 | L33: d005 | M33: Technique Leader | N33: =INDEX(Table3[#All], MATCH(Table13[[#This Row],[Dept_Id]], Table3[[#All],[Dept_Id]], 0), 1) -> Development
A34: 10022 | B34: 7/8/1952 | C34: Shahaf | D34: Famili | E34: M | F34: 8/22/1995 | G34: 9 | H34: B | I34: 1 | J34: 11/4/2005 | K34: 40000 | L34: d005 | M34: Engineer | N34: =INDEX(Table3[#All], MATCH(Table13[[#This Row],[Dept_Id]], Table3[[#All],[Dept_Id]], 0), 1) -> Development
A35: 13616 | B35: 8/30/1961 | C35: Perry | D35: Lorho | E35: F | F35: 8/3/1991 | G35: 7 | H35: C | I35: 0 | K35: 40000 | L35: d005 | M35: Senior Engineer | N35: =INDEX(Table3[#All], MATCH(Table13[[#This Row],[Dept_Id]], Table3[[#All],[Dept_Id]], 0), 1) -> Development
A36: 13616 | B36: 8/30/1961 | C36: Perry | D36: Lorho | E36: F | F36: 8/3/1991 | G36: 7 | H36: C | I36: 0 | K36: 40000 | L36: d008 | M36: Senior Engineer | N36: =INDEX(Table3[#All], MATCH(Table13[[#This Row],[Dept_Id]], Table3[[#All],[Dept_Id]], 0), 1) -> Research
A37: 10023 | B37: 9/29/1953 | C37: Bojan | D37: Montemayor | E37: F | F37: 12/17/1989 | G37: 8 | H37: A | I37: 0 | K37: 47883 | L37: d005 | M37: Engineer | N37: =INDEX(Table3[#All], MATCH(Table13[[#This Row],[Dept_Id]], Table3[[#All],[Dept_Id]], 0), 1) -> Development
A38: 10024 | B38: 9/5/1958 | C38: Suzette | D38: Pettey | E38: F | F38: 5/19/1997 | G38: 3 | H38: A | I38: 0 | K38: 83733 | L38: d004 | M38: Assistant Engineer | N38: =INDEX(Table3[#All], MATCH(Table13[[#This Row],[Dept_Id]], Table3[[#All],[Dept_Id]], 0), 1) -> Production
A39: 246449 | B39: 3/23/1958 | C39: Subbu | D39: Bultermann | E39: F | F39: 3/25/1988 | G39: 9 | H39: C | I39: 0 | K39: 87084 | L39: d007 | M39: Staff | N39: =INDEX(Table3[#All], MATCH(Table13[[#This Row],[Dept_Id]], Table3[[#All],[Dept_Id]], 0), 1) -> Sales
A40: 10025 | B40: 10/31/1958 | C40: Prasadram | D40: Heyers | E40: M | F40: 8/17/1987 | G40: 6 | H40: C | I40: 0 | K40: 40000 | L40: d005 | M40: Technique Leader | N40: =INDEX(Table3[#All], MATCH(Table13[[#This Row],[Dept_Id]], Table3[[#All],[Dept_Id]], 0), 1) -> Development
...

Sheet Dept_Info
A1: Dep_Name | B1: Dept_Id
A2: Marketing | B2: d001
A3: Finance | B3: d002
A4: Human Resources | B4: d003
A5: Production | B5: d004
A6: Development | B6: d005
A7: Quality Management | B7: d006
A8: Sales | B8: d007
A9: Research | B9: d008
A10: Customer Service | B10: d009

Sheet Business Context
B1: Business Context
B2: A mid-sized organization wants to improve its human resource planning, retention strategy, and departmental efficiency. The company has been collecting employee data over the years,
B3: including demographics, work history, performance, and attrition details. Additionally, it maintains a department-level database with department names and IDs.
B5: With rising attrition in some departments and concerns around performance consistency, the HR and Leadership teams want a data-driven understanding of employee trends—both current
B6: and historical—to guide decisions on hiring, promotions, and organizational restructuring.
B8: Problem Statememt
B10: To analyze employee demographics, performance, attrition trends, and departmental structures to deliver insights that:
C11: Improve talent retention strategies
C12: Identify performance bottlenecks
C13: Support department-level workforce planning
C14: Forecast potential risks such as high attrition or skill gaps
B16: Data Description | Data Dictionary
C18: Employee_Info: | F18: Dept_Info:
C19: Columns | D19: Description | F19: Columns | G19: Description
C20: Emp_Id | D20: Employee_id | F20: Dept_id | G20: Department id
C21: DOB | D21: Date of Birth | F21: Dep_Name | G21: Name of the department
C22: first_name | D22: First name of employee
C23: last_name | D23: Last name of employee
C24: Gender | D24: Gender of employee, male or female
C25: DoJ | D25: Date of Joining/ Hiring
C26: no_of_projects | D26: Number of projects worked on
C27: Last_performance_rating | D27: Last year performance ratin--> A, B, C, PIP & S
C28: Left? | D28: Employee left the organization or not? i.e. 0 or 1
C29: last_date | D29: Last date of employement(Exit Date)
C30: Salary | D30: Salary of employee
C31: Dept_Id | D31: Id of Dept in which employee works
C32: Title | D32: Designation of Employee
C35: Ratings description:
C37: Rating | D37: Meaning | E37: Description
C38: A | D38: Excellent / Outstanding | E38: Top performer, exceeds expectations consistently. Often eligible for promotions, bonuses, leadership roles.
C39: B | D39: Good / Meets Expectations | E39: Solid performer. Delivers what’s expected; may occasionally go beyond. Reliable and consistent.
C40: C | D40: Needs Improvement / Below Expectations | E40: Underperforming slightly. May need coaching or upskilling. Not serious yet, but needs monitoring.
C41: PIP | D41: Performance Improvement Plan | E41: Officially under review due to poor performance. Risk of termination if performance doesn't improve.
C42: S | D42: Star Performer / Strategic Contributor | E42: Often used in some companies for elite talent. High-potential, future leader, or mission-critical employee.

Sheet Expected Deliverables
D2: This Mini Project Focuses on Data Transformations, building KPI using Statistical functions & Summarizations using Pivot Tables
B4: 1. Before proceeding with analysis, make sure Date Columns and Salary are in correct format.
B5: 2. In the "Employee_Info" sheet, add a new column that saves the "Dep_Name" for each Employee.
B6: 3. Generate the following KPIs:
C7: a. No. of Employees who left the firm
C8: b. No. of Employees in the Leadership Role
C9: c. Total Employees associated with the firm
B11: 4. Perform the following analysis
C12: a. Employee Retention & Attrition
C13: How many %employees have left the company?
C14: What is the average tenure of employees who left?
C16: b. Performance & Productivity
C17: Is there any correlation between number of projects and performance rating?
C18: Which departments have the highest number of top performers?
C20: c. Salary Analysis
C21: What is the average salary by department?
C22: Are male or female employees paid more on average?
C24: d. Hiring Trends
C25: How many employees joined each year?
C26: Which departments saw the most hiring in the past 2 years?
B28: 5. Are there any employees with poor performance and high salary?
D29: hint: use conditional formattings

Sheet Analysis| Summarization
B3: KPIs: | I3: sum() | J3: countifs()
C4: a. No. of Employees who left the firm | I4: =SUM(Table15[Left?]) -> 44 | J4: =COUNTIFS(Table15[Left?], 1) -> 44
C5: b. No. of Employees in the Leadership Role | I5: =COUNTIFS(Table15[Title], 'New_employee(Cleaned)'!$M$487) -> 29
C6: c. Total Employees associated with the firm | I6: =COUNTIFS(Table15[Left?], 0) -> 456 | J6: =I7-I4 -> 456 | K6: =COUNTBLANK(Table15[last_date]) -> 456
C7: d. Total volume of employees | I7: =COUNTA(Table1[Emp_Id]) -> 500
B10: a. Employee Retention & Attrition
C11: How many %employees have left the company? | I11: What is the average tenure of employees who left?
C13: Left the Org? | D13: Emp_Count | J13: Left? | K13: 1
C14: 0 | D14: 0.912
C15: 1 | D15: 0.088 | J15: Avg. Tenure
C16: Grand Total | D16: 1 | J16: 7.3863636
B19: b. Performance & Productivity
B20: Is there any correlation between number of projects and performance rating? | J20: Which departments have the highest number of top performers?
C22: Projects done | D22: Avg. Ratings | L22: Last_performance_rating | M22: (Multiple Items)
C23: 1 | D23: 3.0181818
C24: 2 | D24: 3.1111111 | L24: Departments | M24: Top Performers
C25: 3 | D25: 3.2631579 | L25: Production | M25: 50
C26: 4 | D26: 3.1428571 | L26: Development | M26: 41
C27: 5 | D27: 2.8363636 | L27: Sales | M27: 28
C28: 6 | D28: 3 | L28: Research | M28: 15
C29: 7 | D29: 3.037037 | L29: Customer Service | M29: 15
C30: 8 | D30: 2.9411765 | L30: Finance | M30: 12
C31: 9 | D31: 3.1764706 | L31: Marketing | M31: 10
C32: 10 | D32: 2.8627451 | L32: Human Resources | M32: 9
C33: Grand Total | D33: 3.03 | L33: Quality Management | M33: 8
L34: Grand Total | M34: 188
D35: =CORREL($C$23:$C$32, $D$23:$D$32) -> -0.36246429
D36: =CORREL($C$23:$C$32, $D$23:$D$32)
B38: c. Salary Analysis
B39: What is the average salary by department? | H39: Are male or female employees paid more on average?
C42: Departments | D42: Avg. Salary | I42: Grenders | J42: Avg. Salary
C43: Customer Service | D43: 48253.889 | I43: F | J43: 54052.299
C44: Development | D44: 48362.054 | I44: M | J44: 52607.634
C45: Finance | D45: 59878.667 | I45: Grand Total | J45: 53168.164
C46: Human Resources | D46: 48254.593
C47: Marketing | D47: 65131.667
C48: Production | D48: 48702.5
C49: Quality Management | D49: 49048.037
C50: Research | D50: 48469.927
C51: Sales | D51: 69925.347
...

Sheet HR ANALYSIS
A1: HR DATA ANALYSIS
D4: ='Analysis| Summarization'!$I$4 -> 44 | G4: ='Analysis| Summarization'!$I$5 -> 29 | J4: ='Analysis| Summarization'!$I$6 -> 456 | M4: ='Analysis| Summarization'!$I$7 -> 500 | P4: =GETPIVOTDATA("[Measures].[Average of Duration]",'Analysis| Summarization'!$J$15) -> 7.3863636
